Workbook

Sheet DCF
D1: 2020 | E1: 2021 | F1: 2022 | G1: 2023 | H1: 2024 | I1: 2025 | J1: 2026EST | K1: 2027EST | L1: 2028EST | M1: 2029EST | N1: 2030EST
B2: NextEraDCFModel
B3: Nathan T. Scott | C3: (Model in Millions)
A4: x | B4: Overview
B5: TickerSymbol | C5: NEE
B6: Date | C6: 46143
B7: StockPrice | C7: 98
B8: StockPriceForecast | C8: =N66 -> 99.895259
B9: Delta | C9: =C8/C7-1 -> 0.019339379
A11: x | B11: Assumptions
B13: Scenario | E13: 1 | G13: 2 | I13: 3
B14: Case Selected | C14: 1 | E14: Revenue G% =80% | G14: Revenue G% =AVG | I14: Revenue G% =110%
B15: WACC | C15: 0.0644 | E15: 0.0644 | G15: 0.0644 | I15: 0.0644
B16: TGR | C16: =CHOOSE(C14,E16,G16,I16) -> 0.025 | E16: 0.025 | G16: 0.03 | I16: 0.035
A18: x | B18: IncomeStatement
B20: Revenue | D20: ='Income Statement20-22'!B2 -> 17997 | E20: ='Income Statement20-22'!C2 -> 17069 | F20: ='Income Statement20-22'!D2 -> 20956 | G20: ='Income Statement23-25'!B2 -> 28114 | H20: ='Income Statement23-25'!C2 -> 24753 | I20: ='Income Statement23-25'!D2 -> 27412 | J20: =J21*I20+I20 -> 29629.538 | K20: =K21*J20+J20 -> 32654.427 | L20: =L21*K20+K20 -> 35331.735 | M20: =M21*L20+L20 -> 36761.107 | N20: =N21*M20+M20 -> 39189.417
B21: %growth | E21: =D20/E20-1 -> 0.054367567 | F21: =E20/F20-1 -> -0.18548387 | G21: =F20/G20-1 -> -0.25460625 | H21: =G20/H20-1 -> 0.13578152 | I21: =H20/I20-1 -> -0.097001313 | J21: =CHOOSE(C14,J23,J24,J25) -> 0.080896606 | K21: =CHOOSE(C14,K23,K24,K25) -> 0.10209033 | L21: =CHOOSE(C14,L23,L24,L25) -> 0.081989135 | M21: =CHOOSE(C14,M23,M24,M25) -> 0.040455746 | N21: =CHOOSE(C14,N23,N24,N25) -> 0.066056502
B23: Pessimistic Case | E23: =E20/D20-1 -> -0.05156415 | F23: =F20/E20-1 -> 0.22772277 | G23: =G20/F20-1 -> 0.34157282 | H23: =H20/G20-1 -> -0.11954898 | I23: =I20/H20-1 -> 0.10742132 | J23: =AVERAGE(E23:I23)*0.8 -> 0.080896606 | K23: =AVERAGE(F23:J23)*0.8 -> 0.10209033 | L23: =AVERAGE(G23:K23)*0.8 -> 0.081989135 | M23: =AVERAGE(H23:L23)*0.8 -> 0.040455746 | N23: =AVERAGE(I23:M23)*0.8 -> 0.066056502
B24: Normal Case | E24: =E20/D20-1 -> -0.05156415 | F24: =F20/E20-1 -> 0.22772277 | G24: =G20/F20-1 -> 0.34157282 | H24: =H20/G20-1 -> -0.11954898 | I24: =I20/H20-1 -> 0.10742132 | J24: =AVERAGE(E24:I24) -> 0.10112076 | K24: =AVERAGE(F24:J24) -> 0.13165774 | L24: =AVERAGE(G24:K24) -> 0.11244473 | M24: =AVERAGE(H24:L24) -> 0.066619114 | N24: =AVERAGE(I24:M24) -> 0.10385273
B25: Optimistic Case | E25: =E20/D20-1 -> -0.05156415 | F25: =F20/E20-1 -> 0.22772277 | G25: =G20/F20-1 -> 0.34157282 | H25: =H20/G20-1 -> -0.11954898 | I25: =I20/H20-1 -> 0.10742132 | J25: =AVERAGE(E25:I25)*1.1 -> 0.11123283 | K25: =AVERAGE(F25:J25)*1.1 -> 0.14704817 | L25: =AVERAGE(G25:K25)*1.1 -> 0.12929976 | M25: =AVERAGE(H25:L25)*1.1 -> 0.082599682 | N25: =AVERAGE(I25:M25)*1.1 -> 0.12707239
B27: EBIT | D27: ='Income Statement20-22'!B10 -> 5116 | E27: ='Income Statement20-22'!C10 -> 2913 | F27: ='Income Statement20-22'!D10 -> 4081 | G27: ='Income Statement23-25'!B10 -> 10237 | H27: ='Income Statement23-25'!C10 -> 7479 | I27: ='Income Statement23-25'!D10 -> 8280 | J27: =J20*J28 -> 7990.0915 | K27: =K20*K28 -> 8726.3262 | L27: =L20*L28 -> 10010.468 | M27: =M20*M28 -> 10958.206 | N27: =N20*N28 -> 11250.772
B28: %sales | D28: =D27/D20 -> 0.2842696 | E28: =E27/E20 -> 0.17066026 | F28: =F27/F20 -> 0.19474136 | G28: =(G27/G20) -> 0.36412464 | H28: =(7479/H20) -> 0.30214519 | I28: =I27/I20 -> 0.30205749 | J28: =AVERAGE(D28:I28) -> 0.26966642 | K28: =AVERAGE(E28:J28) -> 0.26723256 | L28: =AVERAGE(F28:K28) -> 0.28332795 | M28: =AVERAGE(G28:L28) -> 0.29809238 | N28: =AVERAGE(H28:M28) -> 0.287087
B31: TAXES(Benefits) | D31: 44 | E31: 348 | F31: 586 | G31: 1006 | H31: 339 | I31: -802 | J31: =J20*J32 -> 1572.317 | K31: =K20*K32 -> -61.946087 | L31: =L20*L32 -> 1610.5767 | M31: =M20*M32 -> 1538.2208 | N31: =N20*N32 -> 2496.9169
B32: %Tax rate | D32: =D31/D27 -> 0.0086004691 | E32: =E31/E27 -> 0.11946447 | F32: =F31/F27 -> 0.14359226 | G32: =G31/G27 -> 0.098270978 | H32: =H31/H27 -> 0.045326915 | I32: =I31/I27 -> -0.096859903 | J32: =AVERAGE(D32:I32) -> 0.053065864 | K32: =AVERAGE(I32:J32)+0.02 -> -0.0018970196 | L32: =AVERAGE(J32:K32)+0.02 -> 0.045584422 | M32: =AVERAGE(K32:L32)+0.02 -> 0.041843701 | N32: =AVERAGE(L32:M32)+0.02 -> 0.063714062
B35: EBIAT | D35: =D27-D31 -> 5072 | E35: =E27-E31 -> 2565 | F35: =F27-F31 -> 3495 | G35: =G27-G31 -> 9231 | H35: =H27-H31 -> 7140 | I35: =I27-I31 -> 9082 | J35: =J27-J31 -> 6417.7745 | K35: =K27-K31 -> 8788.2723 | ... N35: =N27-N31 -> 8753.8552
B36: %sales | D36: =D35/D20 -> 0.28182475 | E36: =E35/E20 -> 0.15027242 | F36: =F35/F20 -> 0.16677801 | G36: =G35/G20 -> 0.32834175 | H36: =H35/H20 -> 0.28844988 | I36: =I35/I20 -> 0.33131475 | J36: =J35/J20 -> 0.21660056 | K36: =K35/K20 -> 0.26912958 | ... N36: =N35/N20 -> 0.22337294
A38: x | B38: Cash Flow Statement
B40: Plus: D&A | D40: ='Cashflow20-22'!B5 -> 4052 | E40: ='Cashflow20-22'!C5 -> 3924 | F40: ='Cashflow20-22'!D5 -> 4503 | G40: ='CashFlow23-25'!B5 -> 5879 | H40: ='CashFlow23-25'!C5 -> 5462 | I40: ='CashFlow23-25'!D5 -> 6580 | J40: =J20*J41 -> 6615.9388 | K40: =K20*K41 -> 7281.2392 | L40: =L20*L41 -> 7837.5206 | M40: =M20*M41 -> 8197.1618 | N40: =N20*N41 -> 8829.2418
B41: % of sales | D41: =D40/D20 -> 0.22514864 | E41: =E40/E20 -> 0.22989044 | F41: =F40/F20 -> 0.21487879 | G41: =G40/G20 -> 0.2091129 | H41: =H40/H20 -> 0.22066012 | I41: =I40/I20 -> 0.24004086 | J41: =AVERAGE(D41:I41) -> 0.22328863 | K41: =AVERAGE(E41:J41) -> 0.22297862 | L41: =AVERAGE(F41:K41) -> 0.22182665 | M41: =AVERAGE(G41:L41) -> 0.22298463 | N41: =AVERAGE(H41:M41) -> 0.22529659
B43: Less: CapEx | D43: =-'Cashflow20-22'!B24+-'Cashflow20-22'!B27 -> 7514 | E43: =-'Cashflow20-22'!C24+'Cashflow20-22'!C27 -> 7261 | F43: =-'Cashflow20-22'!D24+'Cashflow20-22'!D27 -> 8615 | G43: =-'CashFlow23-25'!B24+'CashFlow23-25'!B27 -> 9241 | H43: =-'CashFlow23-25'!C24+'CashFlow23-25'!C27 -> 7869 | I43: =-'CashFlow23-25'!D24+'CashFlow23-25'!D27 -> 8717 | J43: =J20*J44 -> 10673.082 | K43: =K20*K44 -> 11337.061 | L43: =L20*L44 -> 11814.92 | M43: =M20*M44 -> 12334.826 | N43: =N20*N44 -> 13287.876
B44: % of sales | D44: =D43/D20 -> 0.41751403 | E44: =E43/E20 -> 0.42539106 | F44: =F43/F20 -> 0.41109945 | G44: =G43/G20 -> 0.32869745 | H44: =H43/H20 -> 0.31790086 | I44: =I43/I20 -> 0.31799942 | J44: =AVERAGE(E44:I44) -> 0.36021765 | K44: =AVERAGE(F44:J44) -> 0.34718296 | L44: =AVERAGE(G44:K44) -> 0.33439967 | M44: =AVERAGE(H44:L44) -> 0.33554011 | N44: =AVERAGE(I44:M44) -> 0.33906796
B46: Less: Change in NWC | D46: ='Cashflow20-22'!B18-'Cashflow20-22'!B20 -> -358 | E46: ='Cashflow20-22'!C18-'Cashflow20-22'!C20 -> -2320 | F46: ='Cashflow20-22'!D18-'Cashflow20-22'!D20 -> -3042 | G46: ='CashFlow23-25'!B18-'CashFlow23-25'!B20 -> 1167 | H46: ='CashFlow23-25'!C18-'CashFlow23-25'!C20 -> -1149 | I46: ='CashFlow23-25'!D18-'CashFlow23-25'!D20 -> -1407 | J46: =J47*J20 -> -1998.9102 | K46: =K47*K20 -> -1755.9046 | L46: =L47*L20 -> -1254.0836 | M46: =M47*M20 -> -1870.9698 | N46: =N47*N20 -> -2029.6477
B47: % of sales | D47: =D46/D20 -> -0.019892204 | E47: =E46/E20 -> -0.13591892 | F47: =F46/F20 -> -0.14516129 | G47: =G46/G20 -> 0.041509568 | H47: =H46/H20 -> -0.046418616 | I47: =I46/I20 -> -0.051327886 | J47: =AVERAGE(E47:I47) -> -0.067463428 | K47: =AVERAGE(F47:J47) -> -0.05377233 | L47: =AVERAGE(G47:K47) -> -0.035494538 | M47: =AVERAGE(H47:L47) -> -0.05089536 | N47: =AVERAGE(I47:M47) -> -0.051790708
A49: x | B49: DCF
B51: EBIAT | J51: =J35 -> 6417.7745 | K51: =K35 -> 8788.2723 | L51: =L35 -> 8399.8912 | M51: =M35 -> 9419.9849 | N51: =N35 -> 8753.8552
B52: Plus: D&A | J52: =J40 -> 6615.9388 | K52: =K40 -> 7281.2392 | L52: =L40 -> 7837.5206 | M52: =M40 -> 8197.1618 | N52: =N40 -> 8829.2418
B53: Less: Capex | J53: =J43 -> 10673.082 | K53: =K43 -> 11337.061 | L53: =L43 -> 11814.92 | M53: =M43 -> 12334.826 | N53: =N43 -> 13287.876
B54: Less: Change in WC | J54: =J46 -> -1998.9102 | K54: =K46 -> -1755.9046 | L54: =L46 -> -1254.0836 | M54: =M46 -> -1870.9698 | N54: =N46 -> -2029.6477
B55: FCF | J55: =J51+J52-J53-J54 -> 4359.5411 | K55: =K51+K52-K53-K54 -> 6488.3554 | L55: =L51+L52-L53-L54 -> 5676.5749 | M55: =M51+M52-M53-M54 -> 7153.2906 | N55: =N51+N52-N53-N54 -> 6324.869
B57: Discount period | J57: 1 | K57: =1+J57 -> 2 | L57: =1+K57 -> 3 | M57: =1+L57 -> 4 | N57: =1+M57 -> 5
...

Sheet WACC
B2: WACC calculation
B4: Values in millions
B5: Formula used
B6: WACC = Re*E/V+Rd(1-t)*D/V
B7: Re=Rf+Be*(MRP)
B8: V=D+E
B9: Items | C9: Value | D9: Source
B10: Equity | C10: 188500 | D10: Yahoo Finance
B11: Debt | C11: 84000 | D11: Yahoo Finance
B12: Value(E+D) | C12: =SUM(C10:C11) -> 272500 | D12: Yahoo Finance
B13: E/V | C13: =C10/C12 -> 0.69174312 | D13: Yahoo Finance
B14: D/V | C14: =1-C13 -> 0.30825688 | D14: Yahoo Finance
B16: Re | C16: =C17+C18*C19 -> 0.0765
B17: Rf | C17: 0.042 | D17: U.S. Treasury Yeild
B18: Beta Equity | C18: 0.6 | D18: Yahoo Finance
B19: MRP | C19: 0.0575 | D19: Damodaran
B21: Rd | C21: 0.047 | D21: Google
B22: 1-t | C22: 0.79 | D22: U.S. Corp. Tax Rate
B24: WACC | C24: =C16*C13+C21*C22*C14 -> 0.064363927

Sheet Cashflow20-22
A1: Line Items | B1: 2020 | C1: 2021 | D1: 2022
A2: CASH FLOWS FROM OPERATING ACTIVITIES
A3: Net income | B3: 2,369 | C3: 2,827 | D3: 3,246
A4: Adjustments to reconcile net income to net cash provided by (used in) operating activities:
A5: Depreciation and amortization | B5: 4052 | C5: 3924 | D5: 4503
A6: Nuclear fuel and other amortization | B6: 263 | C6: 290 | D6: 287
A7: Unrealized losses on marked to market derivative contracts – net | B7: 533 | C7: 2,005 | D7: 1,378
A8: Unrealized losses (gains) on equity securities held in NEER's nuclear decommissioning funds – net | B8: -163 | C8: -267 | D8: 461
A9: Foreign currency transaction losses (gains) | B9: 45 | C9: -94 | D9: -104
A10: Deferred income taxes | B10: -78 | C10: 436 | D10: 534
A11: Cost recovery clauses and franchise fees | B11: -121 | C11: -599 | D11: -1465
A12: Equity in losses (earnings) of equity method investees | B12: 1,351 | C12: -666 | D12: -203
A13: Distributions of earnings from equity method investees | B13: 456 | C13: 526 | D13: 541
A14: Gains on disposal of businesses, assets and investments – net | B14: -403 | C14: -146 | D14: -602
A15: Recoverable storm-related costs | B15: -69 | C15: -138 | D15: -811
A16: Other – net | B16: 352 | C16: -59 | D16: 85
A17: Changes in operating assets and liabilities:
A18: Current assets | B18: -364 | C18: -1267 | D18: -1340
A19: Noncurrent assets | B19: -234 | C19: -324 | D19: -89
A20: Current liabilities | B20: -6 | C20: 1053 | D20: 1702
A21: Noncurrent liabilities | B21: 0 | C21: 52 | D21: 139
A22: Net cash provided by operating activities | B22: 7,983 | C22: 7553 | D22: 8262
A23: CASH FLOWS FROM INVESTING ACTIVITIES
A24: Capital expenditures of FPL | B24: -7489 | C24: -7408 | D24: -9067
A25: Independent power and other investments of NEER | B25: -6851 | C25: -8247 | D25: -9541
A26: Nuclear fuel purchases | B26: -245 | C26: -275 | D26: -223
A27: Other capital expenditures | B27: -25 | C27: -147 | D27: -452
A28: Sale of independent power and other investments of NEER | B28: 1,012 | C28: 2,761 | D28: 1,564
A29: Proceeds from sale or maturity of securities in special use funds and other investments | B29: 3,916 | C29: 4,995 | D29: 3,857
A30: Purchases of securities in special use funds and other investments | B30: -4100 | C30: -5310 | D30: -4586
A31: Other – net | B31: 83 | C31: 40 | D31: 89
A32: Net cash used in investing activities | B32: -13699 | C32: -13591 | D32: -18359
A33: CASH FLOWS FROM FINANCING ACTIVITIES
A34: Issuances of long-term debt, including premiums and discounts | B34: 12,404 | C34: 16,683 | D34: 13,856
A35: Retirements of long-term debt | B35: -6103 | C35: -9594 | D35: -4525
A36: Proceeds from differential membership investors | B36: 3,522 | C36: 2,779 | D36: 4,158
A37: Net change in commercial paper | B37: -965 | C37: -169 | D37: 327
A38: Proceeds from other short-term debt | B38: 2,158 | C38: — | D38: 1,755
A39: Repayments of other short-term debt | B39: -2100 | C39: -257 | D39: -1125
A40: Payments from (to) related parties under a cash sweep and credit support agreement – net | B40: -2 | C40: 47 | D40: 240
...

Sheet CashFlow23-25
A1: Line Items | B1: 2023 | C1: 2024 | D1: 2025
A2: CASH FLOWS FROM OPERATING ACTIVITIES
A3: Net income | B3: 6282 | C3: 5698 | D3: 5332
A4: Adjustments to reconcile net income to net cash provided by operating activities:
A5: Depreciation and amortization | B5: 5879 | C5: 5462 | D5: 6580
A6: Nuclear fuel and other amortization | B6: 272 | C6: 299 | D6: 361
A7: Unrealized losses (gains) on marked to market derivative contracts – net | B7: -1949 | C7: -492 | D7: 199
A8: Unrealized losses (gains) on equity securities held in NEER's nuclear decommissioning funds – net | B8: -159 | C8: -107 | D8: -107
A9: Foreign currency transaction losses (gains) | B9: 92 | C9: -85 | D9: 110
A10: Deferred income taxes | B10: 708 | C10: 1,308 | D10: 453
A11: Cost recovery clauses and franchise fees | B11: 1,104 | C11: 1,016 | D11: -89
A12: Equity in losses of equity method investees | B12: 648 | C12: 246 | D12: 184
A13: Distributions of earnings from equity method investees | B13: 712 | C13: 811 | D13: 446
A14: Gains on disposal of businesses, assets and investments – net | B14: -530 | C14: -515 | D14: -439
A15: Recoverable storm-related costs | B15: -399 | C15: -676 | D15: -460
A16: Other – net | B16: 34 | C16: 135 | D16: 288
A17: Changes in operating assets and liabilities:
A18: Current assets | B18: 58 | C18: -382 | D18: -920
A19: Noncurrent assets | B19: -408 | C19: -473 | D19: -440
A20: Current liabilities | B20: -1109 | C20: 767 | D20: 487
A21: Noncurrent liabilities | B21: 66 | C21: 248 | D21: 500
A22: Net cash provided by operating activities | B22: 11301 | C22: 13260 | D22: 12485
A23: CASH FLOWS FROM INVESTING ACTIVITIES
A24: Capital expenditures of FPL | B24: -9302 | C24: -7992 | D24: -8719
A25: Independent power and other investments of NEER | B25: -15565 | C25: -16215 | D25: -15332
A26: Nuclear fuel purchases | B26: -185 | C26: -399 | D26: -553
A27: Other capital expenditures | B27: -61 | C27: -123 | D27: -2
A28: Proceeds from the sale of Florida City Gas business | B28: 924 | C28: — | D28: —
A29: Sale of independent power and other investments of NEER | B29: 1,883 | C29: 2,659 | D29: 1,115
A30: Proceeds from sale or maturity of securities in special use funds and other investments | B30: 4,875 | C30: 5,445 | D30: 5,401
A31: Purchases of securities in special use funds and other investments | B31: -5926 | C31: -5623 | D31: -5893
A32: Other – net | B32: -110 | C32: -16 | D32: 118
A33: Net cash used in investing activities | B33: -23467 | C33: -22264 | D33: -23865
A34: CASH FLOWS FROM FINANCING ACTIVITIES
A35: Issuances of long-term debt, including premiums and discounts | B35: 13,857 | C35: 24,769 | D35: 23,394
A36: Retirements of long-term debt | B36: -7978 | C36: -10113 | D36: -10347
A37: Proceeds from differential membership investors | B37: 2,745 | C37: 2,257 | D37: 3,276
A38: Payments to differential membership investors | B38: -75 | C38: -740 | D38: -516
A39: Net change in commercial paper | B39: 2,941 | C39: -2980 | D39: 285
A40: Proceeds from other short-term debt | B40: 1,980 | C40: 6,575 | D40: 2,558
...

Sheet Income Statement23-25
A1: Line Items | B1: 2023 | C1: 2024 | D1: 2025
A2: OPERATING REVENUES | B2: 28114 | C2: 24753 | D2: 27412
A3: OPERATING EXPENSES
A4: Fuel, purchased power and interchange | B4: 5,457 | C4: 5,029 | D4: 4,944
A5: Other operations and maintenance | B5: 4,681 | C5: 4,857 | D5: 5,399
A6: Depreciation and amortization | B6: 5,879 | C6: 5,462 | D6: 6,580
A7: Taxes other than income taxes and other – net | B7: 2,265 | C7: 2,278 | D7: 2,469
A8: Total operating expenses – net | B8: 18,282 | C8: 17,626 | D8: 19,392
A9: GAINS ON DISPOSAL OF BUSINESSES/ASSETS – NET | B9: 405 | C9: 352 | D9: 260
A10: OPERATING INCOME(EBIT) | B10: 10237 | C10: 7479 | D10: 8280
A11: OTHER INCOME (DEDUCTIONS)
A12: Interest expense | B12: -3324 | C12: -2235 | D12: -4572
A13: Equity in losses of equity method investees | B13: -648 | C13: -246 | D13: -184
A14: Allowance for equity funds used during construction | B14: 161 | C14: 198 | D14: 181
A15: Gains on disposal of investments and other property – net | B15: 125 | C15: 163 | D15: 179
A16: Change in unrealized gains (losses) on equity securities held in NEER's nuclear decommissioning funds – net | B16: 159 | C16: 107 | D16: 107
A17: Other net periodic benefit income | B17: 245 | C17: 235 | D17: 267
A18: Other – net | B18: 333 | C18: 336 | D18: 272
A19: Total other income (deductions) – net | B19: -2949 | C19: -1442 | D19: -3750
A20: INCOME BEFORE INCOME TAXES | B20: 7,288 | C20: 6,037 | D20: 4,530
A21: INCOME TAX EXPENSE (BENEFIT) | B21: 1,006 | C21: 339 | D21: -802
A22: NET INCOME | B22: 6,282 | C22: 5,698 | D22: 5,332
A23: NET LOSS ATTRIBUTABLE TO NONCONTROLLING INTERESTS | B23: 1,028 | C23: 1,248 | D23: 1,503
A24: NET INCOME ATTRIBUTABLE TO NEE | B24: 7310 | C24: 6946 | D24: 6835
A25: Earnings per share attributable to NEE:
A26: Basic | B26: 3.61 | C26: 3.38 | D26: 3.31
A27: Assuming dilution | B27: 3.6 | C27: 3.37 | D27: 3.3

Sheet Income Statement20-22
A1: Line Items | B1: 2020 | C1: 2021 | D1: 2022
A2: OPERATING REVENUES | B2: 17997 | C2: 17069 | D2: 20956
A3: OPERATING EXPENSES
A4: Fuel, purchased power and interchange | B4: 3,539 | C4: 4,527 | D4: 6,389
A5: Other operations and maintenance | B5: 3,934 | C5: 3,981 | D5: 4,428
A6: Depreciation and amortization | B6: 4,052 | C6: 3,924 | D6: 4,503
A7: Taxes other than income taxes and other – net | B7: 1,709 | C7: 1,801 | D7: 2,077
A8: Total operating expenses – net | B8: 13,234 | C8: 14,233 | D8: 17,397
A9: GAINS ON DISPOSAL OF BUSINESSES/ASSETS – NET | B9: 353 | C9: 77 | D9: 522
A10: OPERATING INCOME(EBIT) | B10: 5116 | C10: 2913 | D10: 4081
A11: OTHER INCOME (DEDUCTIONS)
A12: Interest expense | B12: -1950 | C12: -1270 | D12: -585
A13: Equity in earnings (losses) of equity method investees | B13: -1351 | C13: 666 | D13: 203
A14: Allowance for equity funds used during construction | B14: 93 | C14: 142 | D14: 112
A15: Gains on disposal of investments and other property – net | B15: 50 | C15: 70 | D15: 80
A16: Change in unrealized gains (losses) on equity securities held in NEER's nuclear decommissioning funds – net | B16: 163 | C16: 267 | D16: -461
A17: Other net periodic benefit income | B17: 200 | C17: 257 | D17: 202
A18: Other – net | B18: 92 | C18: 130 | D18: 200
A19: Total other income (deductions) – net | B19: -2703 | C19: 262 | D19: -249
A20: INCOME BEFORE INCOME TAXES | B20: 2,413 | C20: 3,175 | D20: 3,832
A21: INCOME TAXES | B21: 44 | C21: 348 | D21: 586
A22: NET INCOME | B22: 2,369 | C22: 2,827 | D22: 3,246
A23: NET LOSS ATTRIBUTABLE TO NONCONTROLLING INTERESTS | B23: 550 | C23: 746 | D23: 901
A24: NET INCOME ATTRIBUTABLE TO NEE | B24: 2919 | C24: 3573 | D24: 4147
A25: Earnings per share attributable to NEE:
A26: Basic | B26: 1.49 | C26: 1.82 | D26: 2.1
A27: Assuming dilution | B27: 1.48 | C27: 1.81 | D27: 2.1

Sheet Balance Sheets 24-25
A1: Line Items | B1: 2024 | C1: 2025
A2: ASSETS
A3: Current assets:
A4: Cash and cash equivalents | B4: 32 | C4: 42
A5: Customer receivables, net of allowances of $25 and $9, respectively | B5: 1,400 | C5: 1,667
A6: Other receivables | B6: 380 | C6: 413
A7: Materials, supplies and fuel inventory | B7: 1,309 | C7: 1,373
A8: Regulatory assets | B8: 1,405 | C8: 401
A9: Other | B9: 257 | C9: 255
A10: Total current assets | B10: 4,783 | C10: 4,151
A11: Other assets:
A12: Electric utility plant and other property – net | B12: 76,166 | C12: 81,755
A13: Special use funds | B13: 6,875 | C13: 7,684
A14: Prepaid benefit costs | B14: 1,954 | C14: 2,072
A15: Regulatory assets | B15: 4,464 | C15: 5,405
A16: Goodwill | B16: 2,965 | C16: 2,965
A17: Other | B17: 934 | C17: 1,126
A18: Total other assets | B18: 93,358 | C18: 101,007
A19: TOTAL ASSETS | B19: 98141 | C19: 105158
A20: LIABILITIES AND EQUITY
A21: Current liabilities:
A22: Commercial paper | B22: 1430 | C22: 1130
A23: Current portion of long-term debt | B23: 1,719 | C23: 641
A24: Accounts payable | B24: 996 | C24: 1,084
A25: Customer deposits | B25: 669 | C25: 685
A26: Accrued interest and taxes | B26: 443 | C26: 470
A27: Accrued construction-related expenditures | B27: 860 | C27: 1,153
A28: Regulatory liabilities | B28: 273 | C28: 344
A29: Other | B29: 1,105 | C29: 687
A30: Total current liabilities | B30: 7,495 | C30: 6,194
A31: Other liabilities and deferred credits:
A32: Long-term debt | B32: 25,026 | C32: 28,041
A33: Asset retirement obligations | B33: 2,276 | C33: 2,158
A34: Deferred income taxes | B34: 9,438 | C34: 10,156
A35: Regulatory liabilities | B35: 10,465 | C35: 11,280
A36: Other | B36: 365 | C36: 343
A37: Total other liabilities and deferred credits | B37: 47,570 | C37: 51,978
A38: TOTAL LIABILITIES | B38: 55,065 | C38: 58,172
A39: COMMITMENTS AND CONTINGENCIES
A40: EQUITY
...
